Workbook
Name ____can435: 43.3
Name ___can430: 40.73
Name ___can435: 43.3
Name ___xlnm.Print_Titles: #N/A
Name __can435: 43.3
Name __xlnm.Print_Titles: #N/A
Name _can435: 43.3
Name ACT_1: "$#REF!.$K$10"
Name ae_1: "$#REF!.$K$2"
Name alround_3_1: "$#REF!.#REF!#REF!"
Name b_1: "$#REF!.$D$11"
Name Beg_Bal_7: "$#REF!.$C$16:$C$327"
Name bel_1: "$#REF!.$AA$55"
Name Bhi_3_1: "$#REF!.#REF!#REF!"
Name bl_3_1: "'file:///D:/New folder/external developement/pondy(s)/TECH SANCTN/Bang (North)_Technical/3 Int electrical.xls'#$'Sqn_Abs_G_6_ '.$#REF!$#REF!"
Name blg4_2: "'file://Natraj/d/DHI/Defence/Market Rate Analysis/Bangalore-Central/3-Int-Ele-Abs.xls'#$'Sqn _Main_ Abs'.$#REF!$#REF!"
Name blg4_3_1: "'file://Natraj/d/DHI/Defence/Market Rate Analysis/Bangalore-Central/3-Int-Ele-Abs.xls'#$'Sqn _Main_ Abs'.$#REF!$#REF!"
Name bli_3_1: "'file:///D:/New folder/external developement/pondy(s)/TECH SANCTN/Bang (North)_Technical/3 Int electrical.xls'#$'WO_Abs _G_2_ 6 DUs'.$#REF!$#REF!"
Name bs_1: "$#REF!.$AR$7"
Name Button_7: "AS_PER_TALLY_31_09_04_ONYX_List1"
Name Button_8: "AS_PER_TALLY_31_09_04_ONYX_List1"
Name C_: #N/A
Name caI_1: "$'mar_ rat_ana'.$#REF!$#REF!"
Name caII_1: "$'mar_ rat_ana'.$#REF!$#REF!"
Name cal_1: "$#REF!.$J$13"
Name cd_1: "$#REF!.$M$5"
Name Cement_1: "$#REF!.$AN$6"
Name ci_1: "$#REF!.$N$4"
Name CompanyInfo2: "JCI"
Name conc13_7: "'file:///../Shoolagir===/Samayasangili Library.xls'#$Spec.$#REF!$#REF!"
Name ContractNumber: "88888888"
Name convey_7: "'file:///../Shoolagir===/Samayasangili Library.xls'#$Spec.$#REF!$#REF!"
Name Data_7: "$#REF!.$A$16:$I$327"
Name Demolishing_lime_concrete_manually_by_mechanical_means_and_disposal_of_material_as_directed: "CPWD 15.1"
Name DocumentNumber: ""
Name du_3_1: "'file:///D:/New folder/external developement/pondy(s)/TECH SANCTN/Bang (North)_Technical/3 Int electrical.xls'#$'Sqn_Abs_G_6_ '.$#REF!$#REF!"
Name dui_3_1: "'file:///D:/New folder/external developement/pondy(s)/TECH SANCTN/Bang (North)_Technical/3 Int electrical.xls'#$'WO_Abs _G_2_ 6 DUs'.$#REF!$#REF!"
Name DW_3_1: "'file:///D:/New folder/external developement/pondy(s)/TECH SANCTN/Bang (North)_Technical/3 Int electrical.xls'#$'Sqn_Abs_G_6_ '.$#REF!$#REF!"
Name el_1: "$#REF!.$AH$6"
Name End_Bal_7: "$#REF!.$I$16:$I$327"
Name et_3_1: "'file://Natraj/d/DHI/Defence/Bangalore (central)/E L E C T/Int-Abs&Take-off(new).xls'#$Sqn_Abs.$#REF!$#REF!"
Name Excel_BuiltIn_Print_Area_3_1_7: "$#REF!.$A$19:$V$60"
Name Excel_BuiltIn_Print_Area_4_1: "$#REF!.$A$19:$I$41"
Name Excel_BuiltIn_Print_Area_5_1: "$#REF!.$A$19:$H$225"
Name Excel_BuiltIn_Print_Area_8_1_7: "$#REF!.$A$1:$I$63"
Name Excel_BuiltIn_Print_Titles_1: "$#REF!.$A$8:$IV$9"
Name Excel_BuiltIn_Print_Titles_2: "$#REF!.$A$8:$IV$9"
Name Excel_BuiltIn_Print_Titles_3: "$#REF!.$A$8:$IV$9"
Name Excel_BuiltIn_Print_Titles_6: "$#REF!.$A$8:$IV$9"
Name Extra_Pay_7: "$#REF!.$E$16:$E$327"
Name fab_1: "$#REF!.$AH$7"
Name fbl_1: "$#REF!.$E$12"
Name fd_3_1: "$#REF!.$#REF!$#REF!"
Name fdfdsf: #N/A
Name fe_3_1: "'file://Natraj/d/DHI/Defence/Market Rate Analysis/Bangalore-Central/3-Int-Ele-Abs.xls'#$'Sqn _Main_ Abs'.$#REF!$#REF!"
Name ff_3_1: "'file:///D:/New folder/external developement/pondy(s)/HPCL/Annexur_A.xls'#$OHT_Abs.$#REF!$#REF!"
Name fi_1: "$#REF!.$AH$3"
Name Fit_3_1: "$#REF!.#REF!#REF!"
Name fitter_3_1: "$#REF!.#REF!#REF!"
Name fr_1: "$#REF!.$AH$3"

Sheet TN SOR data - Labour
A1: Unique_Code | B1: Description | C1: Unit | D1: Base_Rate
A2: I | B2: HIGHLY SKILLED CATEGORY
A3: L-0001 | B3: Technical Assistant Grade-I (B.E.Passed) | C3: Day | D3: 1430
A4: L-0002 | B4: Technical Assistant Grade-II (Diploma in Engg. Passed / B.E. Failed / Degree in Geology for Ground Water Works) | C4: Day | D4: 1289
A5: L-0003 | B5: Technical Assistant Grade-III (Diploma in Engg. Failed / ITI (Civil) Passed) | C5: Day | D5: 1089
A6: L-0004 | B6: Cinema Operator (ITI Passed) | C6: Day | D6: 897
A7: L-0009 | B7: Computer Operator Grade-I [B.E. (Computer Science) / M.Sc., (Computer Science)] | C7: Day | D7: 1430
A8: L-0010 | B8: Computer Operator Grade-II [B.Sc. (Computer Science) / Diploma in Computer Science] | C8: Day | D8: 1289
A9: L-0013 | B9: Wireman Grade-I / Electrician Grade-I | C9: Day | D9: 971
A10: L-0130 | B10: Architect Assistant - Grade I (B.Arch Passed) | C10: Day | D10: 1430
A11: L-0131 | B11: Conservation Architect Assistant - Grade I (B.Arch Passed) | C11: Day | D11: 1430
A12: II | B12: SKILLED CATEGORY
A13: L-0014 | B13: Blacksmith-I Class | C13: Day | D13: 904
A14: L-0016 | B14: Carpenter-I Class | C14: Day | D14: 1148
A15: L-0017 | B15: Cleaner-First Grade | C15: Day | D15: 609
A16: L-0018 | B16: Fitter-I Class | C16: Day | D16: 1036
A17: L-0019 | B17: Fitter (Pipe Laying / Bar Bending)-I Class | C17: Day | D17: 1018
A18: L-0020 | B18: Floor Polisher | C18: Day | D18: 904
A19: L-0021 | B19: Hammer Mazdoor | C19: Day | D19: 726
A20: L-0023 | B20: Driver (Light Duty) | C20: Day | D20: 904
A21: L-0024 | B21: Driver (Heavy Duty) | C21: Day | D21: 965
A22: L-0025 | B22: Maistry, Road Inspector & Work Inspector | C22: Day | D22: 870.9
A23: L-0026 | B23: Maistry, Road Inspector & Work Inspector (Degree Holder) | C23: Day | D23: 965
A24: L-0027 | B24: Skilled Mason Class-I for Heritage Work | C24: Day | D24: 1657
... A49: L-0058 | B49: Electrical Maistry | C49: Day | D49: 1113
A50: III | B50: SEMI SKILLED CATEGORY
A51: L-0059 | B51: Axe Mazdoor | C51: Day | D51: 714
A52: L-0060 | B52: Blacksmith-II Class | C52: Day | D52: 867
A53: L-0061 | B53: Bullocks Pair with Driver (with Bandy) | C53: Day | D53: 1416
A54: L-0062 | B54: Bullocks Single with Driver (with Bandy) | C54: Day | D54: 1018
A55: L-0063 | B55: Carpenter-II Class | C55: Day | D55: 1096
A56: L-0065 | B56: Cleaner-Second Grade | C56: Day | D56: 603
A57: L-0067 | B57: Fitter-II Class | C57: Day | D57: 1006
A58: L-0068 | B58: Fitter (Pipe Laying / Bar Bending)-II Class | C58: Day | D58: 986
A59: L-0069 | B59: Gardener | C59: Day | D59: 714
A60: L-0070 | B60: Jumper Mazdoor | C60: Day | D60: 714
A61: L-0071 | B61: Mason for Brick Work-II Class | C61: Day | D61: 1096
A62: L-0072 | B62: Mason for Stone Work-II Class | C62: Day | D62: 1096
... A83: L-0097 | B83: Electrical Helper | C83: Day | D83: 757
A84: IV | B84: UN-SKILLED CATEGORY
...

Sheet TN SOR data - Material
A1: Unique_Code | B1: Description | C1: Unit | D1: Base_Rate
A2: M-0001 | B2: Cement | C2: MT | D2: 5602.5
A3: M-0002 | B3: Steel | C3: MT | D3: 55665
B4: A. BRICKS AND TILE PRODUCTS
B5: Second Class Table Moulded Chamber Burnt Bricks
A6: M-0003 | B6: Second Class Table Moulded Chamber Burnt Bricks - 9 x 41/2 x 3 | C6: 1000 Nos. | D6: 7887
A7: M-0004 | B7: Second Class Table Moulded Chamber Burnt Bricks - Burnt Brick - 9 x 43/8 x 23/4 | C7: 1000 Nos. | D7: 7585
B8: Second Class Ground Moulded Chamber Burnt Bricks
A9: M-0005 | B9: Second Class Ground Moulded Chamber Burnt Bricks - 9 x 41/2 x 3 | C9: 1000 Nos. | D9: 6795
A10: M-0006 | B10: Second Class Ground Moulded Chamber Burnt Bricks - 9 x 43/8 x 23/4 | C10: 1000 Nos. | D10: 6595
B11: Third Class Country Brick Kiln Burnt
A12: M-0007 | B12: Third Class Country Brick Kiln Burnt - 83/4 x 41/4 x 23/4 | C12: 1000 Nos. | D12: 5709
A13: M-0008 | B13: Third Class Country Brick Kiln Burnt - 83/4 x 41/4 x 21/4 | C13: 1000 Nos. | D13: 4489
A14: M-0009 | B14: Third Class Country Brick Kiln Burnt - 83/4 x 41/4 x 2 | C14: 1000 Nos. | D14: 4299
B15: Fly Ash Bricks
A16: M-0010 | B16: Fly Ash Bricks - 230 x 110 x 70mm | C16: 1000 Nos. | D16: 6595
A17: M-0011 | B17: Fly Ash Bricks - 230 x 110 x 75mm | C17: 1000 Nos. | D17: 6795
B18: Specially Moulded Country Brick for well steining
A19: M-0012 | B19: 83/4 x 41/4 x 2 | C19: 1000 Nos. | D19: 2526
A20: M-0013 | B20: Perforated Bricks 19 x 9 x 9cm | C20: 1000 Nos. | D20: 3854
A21: M-0014 | B21: Terrace Bricks 15 x 7.5 x 2.5cm | C21: 1000 Nos. | D21: 989
A22: M-0015 | B22: Special Bricks 8 x 4 x 2 for Heritage Works | C22: 1000 Nos. | D22: 13365
A23: M-0016 | B23: Terrace Bricks 6 x 3 x 1 for Heritage Works | C23: 1000 Nos. | D23: 10020
B24: Wire Cut Bricks for Heritage Works
A25: M-0017 | B25: Wire Cut Bricks for Heritage Works - Size 9 x 4 x 3 | C25: 1000 Nos. | D25: 13365
A26: M-0018 | B26: Wire Cut Bricks for Heritage Works - Size 9 x 4 x 2 | C26: 1000 Nos. | D26: 11140
A27: M-0019 | B27: Wire Cut Bricks for Heritage Works - Size 9 x 6.5 x 2 | C27: 1000 Nos. | D27: 16705
B28: Flat Tiles
A29: M-0020 | B29: 15cm x 15cm x 12mm | C29: 1000 Nos. | D29: 8087
A30: M-0021 | B30: 15cm x 15cm x 20mm | C30: 1000 Nos. | D30: 9604
B31: Brick Jelly
A32: M-0022 | B32: 40mm size | C32: Cu.M | D32: 705
A33: M-0023 | B33: 20mm size | C33: Cu.M | D33: 786
B34: Pressed Tiles
A35: M-0024 | B35: 20 x 20 x 2cm | C35: 1000 Nos. | D35: 11356
A36: M-0025 | B36: 23 x 23 x 2cm | C36: 1000 Nos. | D36: 16106
B37: Pan Tiles
A38: M-0026 | B38: 23cm x 8cm x 1.7cm | C38: 1000 Nos. | D38: 441.35
A39: M-0027 | B39: 16.5cm x 8cm x 1.7cm | C39: 1000 Nos. | D39: 363.3
B40: Best Mangalore Tiles
...

Sheet SOR data - Equipment
A1: Unique_Code | B1: Description | C1: Unit | D1: Base_Rate
A2: H-0097 | B2: Pumping charges of concrete including hire charges of pump piping work and accessories etc. | C2: cum. | D2: 268.4
A3: H-0098 | B3: Carriage of concrete by Transit Mixer | C3: Km / Cum | D3: 38.06
A4: H-0099 | B4: Cutting Saw Machine | C4: Day | D4: 1729.2
A5: H-0100 | B5: Concrete Joint Cutting Machine | C5: Day | D5: 1152.8
A6: H-0101 | B6: Air Compressor 250 cfm. with two leads for Pneumatic Cutters / Hammers | C6: Day | D6: 2050.4
A7: H-0102 | B7: Excavation of diaphragm wall by Mechanical Grab | C7: Day | D7: 1666.5
A8: H-0103 | B8: Hire and running charges of Bentonite Pump | C8: Day | D8: 4485.8
A9: H-0104 | B9: Hire and running charges of Crane 20 Tonne capacity | C9: Day | D9: 8970.5
A10: H-0105 | B10: Hire and running charges of Crane 40 Tonne capacity | C10: Day | D10: 10252
A11: H-0106 | B11: Hire and running charges of Crane 80 Tonne capacity | C11: Day | D11: 19228
A12: H-0107 | B12: Tractor with Trailar including Driver and Fuel | C12: Hour | D12: 600
A13: H-0108 | B13: Earth Excavator- Wheeled Backhoe loader 0.50 m3 capacity | C13: Hour | D13: 784
... A26: H-0121 | B26: Hire charges for Concrete Tools and Tackles | C26: Day | D26: 2000

Sheet Work Item Package
A1: Work Item Code | B1: Package | C1: Sub-Package | D1: Description | E1: Amount | F1: Unit
A2: A | B2: Earth Work | D2: =A!B2 -> Earthwork | E2: =A!H36 -> 548 | F2: =A!E3 -> Cu.M
A4: B | B4: PCC Work
A5: B1 | C5: PCC - M5 | D5: ='B1'!B2 -> PCC M5 (1:5:10) | E5: ='B1'!H43 -> 5560 | F5: ='B1'!E3 -> Cu.M
A6: B2 | C6: PCC - M7.5 | D6: ='B2'!B2 -> PCC M7.5 (1:4:8) | E6: ='B2'!H43 -> 5672 | F6: ='B2'!E3 -> Cu.M
A7: B3 | C7: PCC - M10 | D7: ='B3'!B2 -> PCC M10 (1:3:6) | E7: ='B3'!H43 -> 5971 | F7: ='B3'!E3 -> Cu.M
A8: B4 | C8: PCC - M15 | D8: ='B4'!B2 -> PCC M15 (1:2:4) | E8: ='B4'!H43 -> 7201 | F8: ='B4'!E3 -> Cu.M
A9: B5 | C9: PCC - M20 | D9: ='B5'!B2 -> PCC M20 (1:1.5:3) | E9: ='B5'!H43 -> 7671 | F9: ='B5'!E3 -> Cu.M
A11: C | B11: RCC Work
A12: C1 | C12: RCC - M20 | D12: ='C1'!B2 -> RCC M20 (1:1.5:3) | E12: ='C1'!H52 -> 22640 | F12: ='C1'!E3 -> Cu.M
A13: C2 | C13: RCC - M25 | D13: ='C2'!B2 -> RCC M25 (1:1:2) | E13: ='C2'!H52 -> 22901 | F13: ='C2'!E3 -> Cu.M
A14: C3 | C14: RCC - M30 | D14: ='C3'!B2 -> RCC M30 (1:0.75:1.5) | E14: ='C3'!H52 -> 23041 | F14: ='C3'!E3 -> Cu.M
A16: D | B16: Masonry Work
A17: D1 | C17: Burnt Brick (230mm X 115mm X 75mm) | D17: ='D1'!B2 -> Masonry Burnt Brick (230mm X 115mm X 75mm) with 1:6 CM mortar | E17: ='D1'!H42 -> 9220 | F17: ='D1'!E3 -> Cu.M
A18: D2 | C18: Cement Block (200mm X 200mm X 400mm)
A19: D3 | C19: Cement Block (150mm X 200mm X 400mm)
A20: D4 | C20: Cement Block (100mm X 200mm X 400mm)
A21: D5 | C21: AAC Block (600mm X 200mm X 200mm)
A22: D6 | C22: AAC Block (600mm X 200mm X 150mm)
A23: D7 | C23: AAC Block (600mm X 200mm X 100mm)
A24: D8 | C24: Flyash Block (600mm X 200mm X 100mm)
A25: D9 | C25: Flyash Block (400mm X 200mm X 200mm)
A26: D10 | C26: Flyash Block (230mm X 110mm X 70mm)
A28: E | B28: Plastering Work
A29: E1 | C29: Plastering Mix 1:2 CM | D29: ='E1'!B2 -> Cement Mortor of 1:2 Plestering Mix for 20mm thick plastering | E29: ='E1'!H40 -> 466 | F29: ='E1'!E3 -> Cu.M
A30: E2 | C30: Plastering Mix 1:3 CM | D30: ='E2'!B2 -> Cement Mortor of 1:3 Plestering Mix for 20mm thick plastering | E30: ='E2'!H40 -> 436 | F30: ='E2'!E3 -> Cu.M
A31: E3 | C31: Plastering Mix 1:4 CM | D31: ='E3'!B2 -> Cement Mortor of 1:4 Plestering Mix for 20mm thick plastering | E31: ='E3'!H40 -> 429 | F31: ='E3'!E3 -> Cu.M
A32: E4 | C32: Plastering Mix 1:5 CM | D32: ='E4'!B2 -> Cement Mortor of 1:5 Plestering Mix for 12mm thick plastering | E32: ='E4'!H40 -> 378 | F32: ='E4'!E3 -> Cu.M
A33: E5 | C33: Plastering Mix 1:6 CM | D33: ='E5'!B2 -> Cement Mortor of 1:6 Plestering Mix for 12mm thick plastering | E33: ='E5'!H40 -> 374 | F33: ='E5'!E3 -> Cu.M
A35: F | B35: Flooring Work
A36: F1 | C36: Marble
A37: F2 | C37: Granite
A38: F3 | C38: Tile
A40: G | B40: Painting Work
A41: G1 | C41: Internal Wall Painting
A42: G2 | C42: Ceiling Painting
A43: G3 | C43: External Wall Painting
A45: H | B45: UPVC
A46: H1 | C46: Doors
A47: H2 | C47: Windows
...

Sheet LEAD & LIFT
B1: Cement, Steel (1 MT) | C1: Lime Stone, Laterite, Brick Jelly, Wood Work, Pond Ash (Wet / Dry), Stone Dust (1Cu.M) | D1: Rough Stone, Bond Stone, Cut Stone, Broken Stone Jelly, Sand, Gravel, Surki, Earth, Crushed Stone Sand (1Cu.M) | E1: Third Class Country Bricks (Kiln Burnt) (1000 Nos.) | F1: Mangalore Tiles (1000 Nos), Machine Pressed Tiles (2000 Nos), Hydraulically Pressed Mosaic Flooring Tiles (1500 Nos) | G1: Bricks II Class Chamber Burnt Bricks (Table Moulded / Ground Moulded), Fly Ash Bricks (1000 Nos.)
A3: Co-efficient | B3: 1 | C3: 1.1 | D3: 1.6 | E3: 1.35 | F3: 1.8 | G3: 2.25
A5: Incidental Charges | B5: 0 | C5: 0 | D5: 0 | E5: 0 | F5: 0 | G5: 0
A7: Transport Distance Charges
A8: From 0 to 10 Km | B8: 7.356 | C8: 8.08 | D8: 11.79 | E8: 9.94 | F8: 13.26 | G8: 16.57
A9: From 10 to 20 Km | B9: 6.3 | C9: 6.92 | D9: 10.08 | E9: 8.51 | F9: 11.35 | G9: 14.19
A10: From 20 to 40 Km | B10: 5.42 | C10: 5.97 | D10: 8.67 | E10: 7.3 | F10: 9.76 | G10: 12.19
A11: From 40 to 80 Km | B11: 4.66 | C11: 5.15 | D11: 8.13 | E11: 6.3 | F11: 8.41 | G11: 10.52
A12: Above 80 Km | B12: 4.26 | C12: 4.69 | D12: 6.82 | E12: 5.76 | F12: 7.68 | G12: 9.6
A14: Lift Charges
A15: Loading Charges | B15: 135.5 | C15: 64.65 | D15: 44.25 | E15: 63.6 | F15: 63.6 | G15: 63.6
A16: Unloading Charges | B16: 135.5 | C16: 64.65 | D16: 44.25 | E16: 63.6 | F16: 63.6 | G16: 63.6
A19: Items | B19: Distance (Km) | C19: Total Transport Charges | D19: Total Lift Charges | E19: Total Charges
A20: Cement | B20: 15 | C20: =( MIN(B$20,10)*B$8 + MAX(MIN(B$20-10,10),0)*B$9 + MAX(MIN(B$20-20,20),0)*B$10 + MAX(MIN(B$20-40,40),0)*B$11 + MAX(B$20-80,0)*B$12 ) -> 105.06 | D20: =SUM(B15:B16) -> 271 | E20: =SUM(C20:D20) -> 376.06
A21: Steel | B21: 11 | C21: =( MIN(B$21,10)*B$8 + MAX(MIN(B$21-10,10),0)*B$9 + MAX(MIN(B$21-20,20),0)*B$10 + MAX(MIN(B$21-40,40),0)*B$11 + MAX(B$21-80,0)*B$12 ) -> 79.86 | D21: =SUM(B15:B16) -> 271 | E21: =SUM(C21:D21) -> 350.86
A22: Course Aggregate | B22: 20 | C22: =( MIN(B$22,10)*D$8 + MAX(MIN(B$22-10,10),0)*D$9 + MAX(MIN(B$22-20,20),0)*D$10 + MAX(MIN(B$22-40,40),0)*D$11 + MAX(B$22-80,0)*D$12 ) -> 218.7 | D22: =SUM(D15:D16) -> 88.5 | E22: =SUM(C22:D22) -> 307.2
A23: Fine Aggregate | B23: 25 | C23: =( MIN(B$23,10)*D$8 + MAX(MIN(B$23-10,10),0)*D$9 + MAX(MIN(B$23-20,20),0)*D$10 + MAX(MIN(B$23-40,40),0)*D$11 + MAX(B$23-80,0)*D$12 ) -> 262.05 | D23: =SUM(D15:D16) -> 88.5 | E23: =SUM(C23:D23) -> 350.55
A24: Burnt Brick (230mm X 115mm X 75mm) | B24: 15 | C24: =( MIN(B$24,10)*G$8 + MAX(MIN(B$24-10,10),0)*G$9 + MAX(MIN(B$24-20,20),0)*G$10 + MAX(MIN(B$24-40,40),0)*G$11 + MAX(B$24-80,0)*G$12 ) -> 236.65 | D24: =SUM(G15:G16) -> 127.2 | E24: =SUM(C24:D24) -> 363.85

Sheet A
A1: Work Item | B1: A
B2: Earthwork
B3: Rate Analysis for | D3: 100 | E3: Cu.M
A5: Unique_Code | B5: Item | C5: Description | D5: Quantity | E5: Unit | F5: Rate | G5: Per | H5: Amount | I5: Remark
B6: Material
B9: Labour
A10: ='TN SOR data - Labour'!A82 -> L-0096 | B10: Earthworker | C10: =VLOOKUP(A10,'TN SOR data - Labour'!A:D,2,FALSE) -> Heavy Mazdoor | D10: 2 | E10: Day | F10: =VLOOKUP(A10,'TN SOR data - Labour'!A:D,4,FALSE) -> 832 | G10: =VLOOKUP(A10,Table1[],3,FALSE) -> Day | H10: =PRODUCT(D10,F10) -> 1664
A11: ='TN SOR data - Labour'!A63 -> L-0073 | B11: Male Coolie | C11: =VLOOKUP(A11,'TN SOR data - Labour'!A:D,2,FALSE) -> Mazdoor Category-I | D11: 10 | E11: Day | F11: =VLOOKUP(A11,'TN SOR data - Labour'!A:D,4,FALSE) -> 766 | G11: =VLOOKUP(A11,Table1[],3,FALSE) -> Day | H11: =PRODUCT(D11,F11) -> 7660
A12: ='TN SOR data - Labour'!A85 -> L-0098 | B12: Female Coolie | C12: =VLOOKUP(A12,'TN SOR data - Labour'!A:D,2,FALSE) -> Mazdoor Category-II | D12: 10 | E12: Day | F12: =VLOOKUP(A12,'TN SOR data - Labour'!A:D,4,FALSE) -> 628 | G12: =VLOOKUP(A12,Table1[],3,FALSE) -> Day | H12: =PRODUCT(D12,F12) -> 6280
B14: Equipment
A15: ='SOR data - Equipment'!A16 -> H-0111 | B15: Excavator | C15: =VLOOKUP(A15,'SOR data - Equipment'!A:D,2,FALSE) -> Earth Excavator- Crawler / Tracked Excavator 1 m3 capacity | D15: 8 | E15: Hours | F15: =VLOOKUP(A15,'SOR data - Equipment'!A:D,4,FALSE) -> 2000 | G15: =VLOOKUP(A15,'SOR data - Equipment'!A:D,3,FALSE) -> Hour | H15: =PRODUCT(D15,F15) -> 16000
A16: ='SOR data - Equipment'!A20 -> H-0115 | B16: Loader | C16: =VLOOKUP(A16,'SOR data - Equipment'!A:D,2,FALSE) -> Hire running charges for Loader | D16: 8 | E16: Hours | F16: =VLOOKUP(A16,'SOR data - Equipment'!A:D,4,FALSE) -> 729 | G16: =VLOOKUP(A16,'SOR data - Equipment'!A:D,3,FALSE) -> Hour | H16: =PRODUCT(D16,F16) -> 5832
A17: ='SOR data - Equipment'!A19 -> H-0114 | B17: Tipper | C17: =VLOOKUP(A17,'SOR data - Equipment'!A:D,2,FALSE) -> Hire running charges for Tipper | D17: 8 | E17: Hours | F17: =VLOOKUP(A17,'SOR data - Equipment'!A:D,4,FALSE) -> 938 | G17: =VLOOKUP(A17,'SOR data - Equipment'!A:D,3,FALSE) -> Hour | H17: =PRODUCT(D17,F17) -> 7504
A18: ='SOR data - Equipment'!A21 -> H-0116 | B18: Tools and Tackles | C18: =VLOOKUP(A18,'SOR data - Equipment'!A:D,2,FALSE) -> Hire charges for Excavation Tools and Tackles | D18: 1 | E18: LS | F18: =VLOOKUP(A18,'SOR data - Equipment'!A:D,4,FALSE) -> 500 | G18: =VLOOKUP(A18,'SOR data - Equipment'!A:D,3,FALSE) -> Day | H18: =PRODUCT(D18,F18) -> 500
B20: Total - A | H20: =SUM(H7:H7,H10:H12,H15:H18) -> 45440
B22: Water Charges @ | F22: 0.015 | H22: =PRODUCT(H20,F22) -> 681.6
B23: Electrical Charges @ | F23: 0.01 | H23: =PRODUCT(H20,F23) -> 454.4
B24: Local Liaisoning & Dispute @ | F24: 0.005 | H24: =PRODUCT(H20,F24) -> 227.2
B25: Supervision Charges @ | F25: 0.01 | H25: =PRODUCT(H20,F25) -> 454.4
B26: Engineering & Testing Charges @ | F26: 0.005 | H26: =PRODUCT(H20,F26) -> 227.2
B27: Site Establishment @ | F27: 0.005 | H27: =PRODUCT(H20,F27) -> 227.2
B28: Insurance (Labour & Equipments) @ | F28: 0.005 | H28: =PRODUCT(H20,F28) -> 227.2
B29: Contingency, Safety Compliance & Overhead Charges @ | F29: 0.05 | H29: =PRODUCT(H20,F29) -> 2272
B30: Profit @ | F30: 0.1 | H30: =PRODUCT(H20,F30) -> 4544
B32: Total - B | H32: =SUM(H22:H30) -> 9315.2
B34: Rate for 100Cu.M | H34: =SUM(H20,H32) -> 54755.2
B36: Rate for 1Cu.M | H36: =CEILING(H34/D3,1) -> 548

Sheet B1
A1: Work Item | B1: B1
B2: PCC M5 (1:5:10)
B3: Rate Analysis for | D3: 10 | E3: Cu.M
A5: Unique_Code | B5: Item | C5: Description | D5: Quantity | E5: Unit | F5: Rate | G5: Per | H5: Amount | I5: Remark
B6: Material
A7: ='TN SOR data - Material'!A75 -> M-0086 | B7: Coarse Aggregate | C7: =VLOOKUP(A7,Table24[#All],2,FALSE) -> HBGS Jelly 40mm size | D7: 9.5 | E7: Cu.M | F7: =VLOOKUP(A7,'TN SOR data - Material'!A:D,4,FALSE) -> 1362.9 | G7: =VLOOKUP(A7,Table24[],3,FALSE) -> Cu.M | H7: =PRODUCT(D7,F7) -> 12947.55
A8: ='TN SOR data - Material'!A94 -> M-0125 | B8: Fine Aggragete | C8: =VLOOKUP(A8,Table24[#All],2,FALSE) -> Crushed Stone Sand (Commercially called M-Sand) | D8: 4.75 | E8: Cu.M | F8: =VLOOKUP(A8,'TN SOR data - Material'!A:D,4,FALSE) -> 1578.8 | G8: =VLOOKUP(A8,Table24[],3,FALSE) -> Cu.M | H8: =PRODUCT(D8,F8) -> 7499.3
A9: ='TN SOR data - Material'!A2 -> M-0001 | B9: Cement (28.5 bags or 0.95 Cu.M) | C9: =VLOOKUP(A9,Table24[#All],2,FALSE) -> Cement | D9: 1.368 | E9: MT | F9: =VLOOKUP(A9,'TN SOR data - Material'!A:D,4,FALSE) -> 5602.5 | G9: =VLOOKUP(A9,Table24[],3,FALSE) -> MT | H9: =PRODUCT(D9,F9) -> 7664.22
B11: Labour
A12: ='TN SOR data - Labour'!A26 -> L-0029 | B12: Mistri (Head Mason) | C12: =VLOOKUP(A12,'TN SOR data - Labour'!A:D,2,FALSE) -> Mason for Brick Work-I Class | D12: 0.5 | E12: Day | F12: =VLOOKUP(A12,'TN SOR data - Labour'!A:D,4,FALSE) -> 1174 | G12: =VLOOKUP(A12,Table1[],3,FALSE) -> Day | H12: =PRODUCT(D12,F12) -> 587
A13: ='TN SOR data - Labour'!A26 -> L-0029 | B13: Mason | C13: =VLOOKUP(A13,'TN SOR data - Labour'!A:D,2,FALSE) -> Mason for Brick Work-I Class | D13: 1.5 | E13: Day | F13: =VLOOKUP(A13,'TN SOR data - Labour'!A:D,4,FALSE) -> 1174 | G13: =VLOOKUP(A13,Table1[],3,FALSE) -> Day | H13: =PRODUCT(D13,F13) -> 1761
A14: ='TN SOR data - Labour'!A63 -> L-0073 | B14: Male Coolie | C14: =VLOOKUP(A14,'TN SOR data - Labour'!A:D,2,FALSE) -> Mazdoor Category-I | D14: 4 | E14: Day | F14: =VLOOKUP(A14,'TN SOR data - Labour'!A:D,4,FALSE) -> 766 | G14: =VLOOKUP(A14,Table1[],3,FALSE) -> Day | H14: =PRODUCT(D14,F14) -> 3064
A15: ='TN SOR data - Labour'!A85 -> L-0098 | B15: Female Coolie | C15: =VLOOKUP(A15,'TN SOR data - Labour'!A:D,2,FALSE) -> Mazdoor Category-II | D15: 4 | E15: Day | F15: =VLOOKUP(A15,'TN SOR data - Labour'!A:D,4,FALSE) -> 628 | G15: =VLOOKUP(A15,Table1[],3,FALSE) -> Day | H15: =PRODUCT(D15,F15) -> 2512
B17: Equipment
A18: ='SOR data - Equipment'!A15 -> H-0110 | B18: Concrete Mixer | C18: =VLOOKUP(A18,'SOR data - Equipment'!A:D,2,FALSE) -> Mixer Machine with Hopper | D18: 1 | E18: Day | F18: =VLOOKUP(A18,'SOR data - Equipment'!A:D,4,FALSE) -> 1500 | G18: =VLOOKUP(A18,'SOR data - Equipment'!A:D,3,FALSE) -> Day | H18: =PRODUCT(D18,F18) -> 1500
A19: ='SOR data - Equipment'!A14 -> H-0109 | B19: Vibrator | C19: =VLOOKUP(A19,'SOR data - Equipment'!A:D,2,FALSE) -> Hire Charges for Surface Vibrator or Earth Rammer including Fuel | D19: 1 | E19: Day | F19: =VLOOKUP(A19,'SOR data - Equipment'!A:D,4,FALSE) -> 1000 | G19: =VLOOKUP(A19,'SOR data - Equipment'!A:D,3,FALSE) -> Day | H19: =PRODUCT(D19,F19) -> 1000
A20: ='SOR data - Equipment'!A24 -> H-0119 | B20: Formwork | C20: =VLOOKUP(A20,'SOR data - Equipment'!A:D,2,FALSE) -> Hire charges for Concrete Formwork | D20: 1 | E20: LS | F20: =VLOOKUP(A20,'SOR data - Equipment'!A:D,4,FALSE) -> 2500 | G20: =VLOOKUP(A20,'SOR data - Equipment'!A:D,3,FALSE) -> Day | H20: =PRODUCT(D20,F20) -> 2500
B22: Lead & Lift Charges
B23: ='LEAD & LIFT'!A22 -> Course Aggregate | D23: =D7 -> 9.5 | E23: =E7 -> Cu.M | F23: =VLOOKUP(B23,Table13[#All],5,FALSE) -> 307.2 | G23: =G7 -> Cu.M | H23: =(F23*D23) -> 2918.4
B24: ='LEAD & LIFT'!A23 -> Fine Aggregate | D24: =D8 -> 4.75 | E24: =E8 -> Cu.M | F24: =VLOOKUP(B24,Table13[#All],5,FALSE) -> 350.55 | G24: =G8 -> Cu.M | H24: =(F24*D24) -> 1665.1125
B25: ='LEAD & LIFT'!A20 -> Cement | D25: =D9 -> 1.368 | E25: =E9 -> MT | F25: =VLOOKUP(B25,Table13[#All],5,FALSE) -> 376.06 | G25: =G9 -> MT | H25: =(F25*D25) -> 514.45008
B27: Total - A | H27: =SUM(H7:H9,H12:H15,H18:H20,H23:H25) -> 46133.033
B29: Water Charges @ | F29: 0.015 | H29: =PRODUCT(H27,F29) -> 691.99549
B30: Electrical Charges @ | F30: 0.01 | H30: =PRODUCT(H27,F30) -> 461.33033
B31: Local Liaisoning & Dispute @ | F31: 0.005 | H31: =PRODUCT(H27,F31) -> 230.66516
B32: Supervision Charges @ | F32: 0.01 | H32: =PRODUCT(H27,F32) -> 461.33033
B33: Engineering & Testing Charges @ | F33: 0.005 | H33: =PRODUCT(H27,F33) -> 230.66516
B34: Site Establishment @ | F34: 0.005 | H34: =PRODUCT(H27,F34) -> 230.66516
B35: Insurance (Labour & Equipments) @ | F35: 0.005 | H35: =PRODUCT(H27,F35) -> 230.66516
B36: Contingency, Safety Compliance & Overhead Charges @ | F36: 0.05 | H36: =PRODUCT(H27,F36) -> 2306.6516
B37: Profit @ | F37: 0.1 | H37: =PRODUCT(H27,F37) -> 4613.3033
B39: Total - B | H39: =SUM(H29:H37) -> 9457.2717
B41: Rate for 10Cu.M | H41: =SUM(H27,H39) -> 55590.304
B43: Rate for 1Cu.M | H43: =CEILING(H41/D3,1) -> 5560

Sheet B2
A1: Work Item | B1: B2
B2: PCC M7.5 (1:4:8)
B3: Rate Analysis for | D3: 10 | E3: Cu.M
A5: Unique_Code | B5: Item | C5: Description | D5: Quantity | E5: Unit | F5: Rate | G5: Per | H5: Amount | I5: Remark
B6: Material
A7: ='TN SOR data - Material'!A75 -> M-0086 | B7: Coarse Aggregate | C7: =VLOOKUP(A7,Table24[#All],2,FALSE) -> HBGS Jelly 40mm size | D7: 9.2 | E7: Cu.M | F7: =VLOOKUP(A7,'TN SOR data - Material'!A:D,4,FALSE) -> 1362.9 | G7: =VLOOKUP(A7,Table24[],3,FALSE) -> Cu.M | H7: =PRODUCT(D7,F7) -> 12538.68
A8: ='TN SOR data - Material'!A94 -> M-0125 | B8: Fine Aggragete | C8: =VLOOKUP(A8,Table24[#All],2,FALSE) -> Crushed Stone Sand (Commercially called M-Sand) | D8: 4.6 | E8: Cu.M | F8: =VLOOKUP(A8,'TN SOR data - Material'!A:D,4,FALSE) -> 1578.8 | G8: =VLOOKUP(A8,Table24[],3,FALSE) -> Cu.M | H8: =PRODUCT(D8,F8) -> 7262.48
A9: ='TN SOR data - Material'!A2 -> M-0001 | B9: Cement (34.5 bags or 1.15 Cu.M) | C9: =VLOOKUP(A9,Table24[#All],2,FALSE) -> Cement | D9: 1.656 | E9: MT | F9: =VLOOKUP(A9,'TN SOR data - Material'!A:D,4,FALSE) -> 5602.5 | G9: =VLOOKUP(A9,Table24[],3,FALSE) -> MT | H9: =PRODUCT(D9,F9) -> 9277.74
B11: Labour
A12: ='TN SOR data - Labour'!A26 -> L-0029 | B12: Mistri (Head Mason) | C12: =VLOOKUP(A12,'TN SOR data - Labour'!A:D,2,FALSE) -> Mason for Brick Work-I Class | D12: 0.5 | E12: Day | F12: =VLOOKUP(A12,'TN SOR data - Labour'!A:D,4,FALSE) -> 1174 | G12: =VLOOKUP(A12,Table1[],3,FALSE) -> Day | H12: =PRODUCT(D12,F12) -> 587
A13: ='TN SOR data - Labour'!A26 -> L-0029 | B13: Mason | C13: =VLOOKUP(A13,'TN SOR data - Labour'!A:D,2,FALSE) -> Mason for Brick Work-I Class | D13: 1.5 | E13: Day | F13: =VLOOKUP(A13,'TN SOR data - Labour'!A:D,4,FALSE) -> 1174 | G13: =VLOOKUP(A13,Table1[],3,FALSE) -> Day | H13: =PRODUCT(D13,F13) -> 1761
A14: ='TN SOR data - Labour'!A63 -> L-0073 | B14: Male Coolie | C14: =VLOOKUP(A14,'TN SOR data - Labour'!A:D,2,FALSE) -> Mazdoor Category-I | D14: 4 | E14: Day | F14: =VLOOKUP(A14,'TN SOR data - Labour'!A:D,4,FALSE) -> 766 | G14: =VLOOKUP(A14,Table1[],3,FALSE) -> Day | H14: =PRODUCT(D14,F14) -> 3064
A15: ='TN SOR data - Labour'!A85 -> L-0098 | B15: Female Coolie | C15: =VLOOKUP(A15,'TN SOR data - Labour'!A:D,2,FALSE) -> Mazdoor Category-II | D15: 4 | E15: Day | F15: =VLOOKUP(A15,'TN SOR data - Labour'!A:D,4,FALSE) -> 628 | G15: =VLOOKUP(A15,Table1[],3,FALSE) -> Day | H15: =PRODUCT(D15,F15) -> 2512
B17: Equipment
A18: ='SOR data - Equipment'!A15 -> H-0110 | B18: Concrete Mixer | C18: =VLOOKUP(A18,'SOR data - Equipment'!A:D,2,FALSE) -> Mixer Machine with Hopper | D18: 1 | E18: Day | F18: =VLOOKUP(A18,'SOR data - Equipment'!A:D,4,FALSE) -> 1500 | G18: =VLOOKUP(A18,'SOR data - Equipment'!A:D,3,FALSE) -> Day | H18: =PRODUCT(D18,F18) -> 1500
A19: ='SOR data - Equipment'!A14 -> H-0109 | B19: Vibrator | C19: =VLOOKUP(A19,'SOR data - Equipment'!A:D,2,FALSE) -> Hire Charges for Surface Vibrator or Earth Rammer including Fuel | D19: 1 | E19: Day | F19: =VLOOKUP(A19,'SOR data - Equipment'!A:D,4,FALSE) -> 1000 | G19: =VLOOKUP(A19,'SOR data - Equipment'!A:D,3,FALSE) -> Day | H19: =PRODUCT(D19,F19) -> 1000
A20: ='SOR data - Equipment'!A24 -> H-0119 | B20: Formwork | C20: =VLOOKUP(A20,'SOR data - Equipment'!A:D,2,FALSE) -> Hire charges for Concrete Formwork | D20: 1 | E20: LS | F20: =VLOOKUP(A20,'SOR data - Equipment'!A:D,4,FALSE) -> 2500 | G20: =VLOOKUP(A20,'SOR data - Equipment'!A:D,3,FALSE) -> Day | H20: =PRODUCT(D20,F20) -> 2500
B22: Lead & Lift Charges
B23: ='LEAD & LIFT'!A22 -> Course Aggregate | D23: =D7 -> 9.2 | E23: =E7 -> Cu.M | F23: =VLOOKUP(B23,Table13[#All],5,FALSE) -> 307.2 | G23: =G7 -> Cu.M | H23: =(F23*D23) -> 2826.24
B24: ='LEAD & LIFT'!A23 -> Fine Aggregate | D24: =D8 -> 4.6 | E24: =E8 -> Cu.M | F24: =VLOOKUP(B24,Table13[#All],5,FALSE) -> 350.55 | G24: =G8 -> Cu.M | H24: =(F24*D24) -> 1612.53
B25: ='LEAD & LIFT'!A20 -> Cement | D25: =D9 -> 1.656 | E25: =E9 -> MT | F25: =VLOOKUP(B25,Table13[#All],5,FALSE) -> 376.06 | G25: =G9 -> MT | H25: =(F25*D25) -> 622.75536
B27: Total - A | H27: =SUM(H7:H9,H12:H15,H18:H20,H23:H25) -> 47064.425
B29: Water Charges @ | F29: 0.015 | H29: =PRODUCT(H27,F29) -> 705.96638
B30: Electrical Charges @ | F30: 0.01 | H30: =PRODUCT(H27,F30) -> 470.64425
B31: Local Liaisoning & Dispute @ | F31: 0.005 | H31: =PRODUCT(H27,F31) -> 235.32213
B32: Supervision Charges @ | F32: 0.01 | H32: =PRODUCT(H27,F32) -> 470.64425
B33: Engineering & Testing Charges @ | F33: 0.005 | H33: =PRODUCT(H27,F33) -> 235.32213
B34: Site Establishment @ | F34: 0.005 | H34: =PRODUCT(H27,F34) -> 235.32213
B35: Insurance (Labour & Equipments) @ | F35: 0.005 | H35: =PRODUCT(H27,F35) -> 235.32213
B36: Contingency, Safety Compliance & Overhead Charges @ | F36: 0.05 | H36: =PRODUCT(H27,F36) -> 2353.2213
B37: Profit @ | F37: 0.1 | H37: =PRODUCT(H27,F37) -> 4706.4425
B39: Total - B | H39: =SUM(H29:H37) -> 9648.2072
B41: Rate for 10Cu.M | H41: =SUM(H27,H39) -> 56712.633
B43: Rate for 1Cu.M | H43: =CEILING(H41/D3,1) -> 5672

Sheet B3
A1: Work Item | B1: B3
B2: PCC M10 (1:3:6)
B3: Rate Analysis for | D3: 10 | E3: Cu.M
A5: Unique_Code | B5: Item | C5: Description | D5: Quantity | E5: Unit | F5: Rate | G5: Per | H5: Amount | I5: Remark
B6: Material
A7: ='TN SOR data - Material'!A75 -> M-0086 | B7: Coarse Aggregate | C7: =VLOOKUP(A7,Table24[#All],2,FALSE) -> HBGS Jelly 40mm size | D7: 9 | E7: Cu.M | F7: =VLOOKUP(A7,'TN SOR data - Material'!A:D,4,FALSE) -> 1362.9 | G7: =VLOOKUP(A7,Table24[],3,FALSE) -> Cu.M | H7: =PRODUCT(D7,F7) -> 12266.1
A8: ='TN SOR data - Material'!A94 -> M-0125 | B8: Fine Aggragete | C8: =VLOOKUP(A8,Table24[#All],2,FALSE) -> Crushed Stone Sand (Commercially called M-Sand) | D8: 4.5 | E8: Cu.M | F8: =VLOOKUP(A8,'TN SOR data - Material'!A:D,4,FALSE) -> 1578.8 | G8: =VLOOKUP(A8,Table24[],3,FALSE) -> Cu.M | H8: =PRODUCT(D8,F8) -> 7104.6
A9: ='TN SOR data - Material'!A2 -> M-0001 | B9: Cement (45 bags or 1.50 Cu.M) | C9: =VLOOKUP(A9,Table24[#All],2,FALSE) -> Cement | D9: 2.16 | E9: MT | F9: =VLOOKUP(A9,'TN SOR data - Material'!A:D,4,FALSE) -> 5602.5 | G9: =VLOOKUP(A9,Table24[],3,FALSE) -> MT | H9: =PRODUCT(D9,F9) -> 12101.4
B11: Labour
A12: ='TN SOR data - Labour'!A26 -> L-0029 | B12: Mistri (Head Mason) | C12: =VLOOKUP(A12,'TN SOR data - Labour'!A:D,2,FALSE) -> Mason for Brick Work-I Class | D12: 0.5 | E12: Day | F12: =VLOOKUP(A12,'TN SOR data - Labour'!A:D,4,FALSE) -> 1174 | G12: =VLOOKUP(A12,Table1[],3,FALSE) -> Day | H12: =PRODUCT(D12,F12) -> 587
A13: ='TN SOR data - Labour'!A26 -> L-0029 | B13: Mason | C13: =VLOOKUP(A13,'TN SOR data - Labour'!A:D,2,FALSE) -> Mason for Brick Work-I Class | D13: 1.5 | E13: Day | F13: =VLOOKUP(A13,'TN SOR data - Labour'!A:D,4,FALSE) -> 1174 | G13: =VLOOKUP(A13,Table1[],3,FALSE) -> Day | H13: =PRODUCT(D13,F13) -> 1761
A14: ='TN SOR data - Labour'!A63 -> L-0073 | B14: Male Coolie | C14: =VLOOKUP(A14,'TN SOR data - Labour'!A:D,2,FALSE) -> Mazdoor Category-I | D14: 4 | E14: Day | F14: =VLOOKUP(A14,'TN SOR data - Labour'!A:D,4,FALSE) -> 766 | G14: =VLOOKUP(A14,Table1[],3,FALSE) -> Day | H14: =PRODUCT(D14,F14) -> 3064
A15: ='TN SOR data - Labour'!A85 -> L-0098 | B15: Female Coolie | C15: =VLOOKUP(A15,'TN SOR data - Labour'!A:D,2,FALSE) -> Mazdoor Category-II | D15: 4 | E15: Day | F15: =VLOOKUP(A15,'TN SOR data - Labour'!A:D,4,FALSE) -> 628 | G15: =VLOOKUP(A15,Table1[],3,FALSE) -> Day | H15: =PRODUCT(D15,F15) -> 2512
B17: Equipment
A18: ='SOR data - Equipment'!A15 -> H-0110 | B18: Concrete Mixer | C18: =VLOOKUP(A18,'SOR data - Equipment'!A:D,2,FALSE) -> Mixer Machine with Hopper | D18: 1 | E18: Day | F18: =VLOOKUP(A18,'SOR data - Equipment'!A:D,4,FALSE) -> 1500 | G18: =VLOOKUP(A18,'SOR data - Equipment'!A:D,3,FALSE) -> Day | H18: =PRODUCT(D18,F18) -> 1500
A19: ='SOR data - Equipment'!A14 -> H-0109 | B19: Vibrator | C19: =VLOOKUP(A19,'SOR data - Equipment'!A:D,2,FALSE) -> Hire Charges for Surface Vibrator or Earth Rammer including Fuel | D19: 1 | E19: Day | F19: =VLOOKUP(A19,'SOR data - Equipment'!A:D,4,FALSE) -> 1000 | G19: =VLOOKUP(A19,'SOR data - Equipment'!A:D,3,FALSE) -> Day | H19: =PRODUCT(D19,F19) -> 1000
A20: ='SOR data - Equipment'!A24 -> H-0119 | B20: Formwork | C20: =VLOOKUP(A20,'SOR data - Equipment'!A:D,2,FALSE) -> Hire charges for Concrete Formwork | D20: 1 | E20: LS | F20: =VLOOKUP(A20,'SOR data - Equipment'!A:D,4,FALSE) -> 2500 | G20: =VLOOKUP(A20,'SOR data - Equipment'!A:D,3,FALSE) -> Day | H20: =PRODUCT(D20,F20) -> 2500
B22: Lead & Lift Charges
B23: ='LEAD & LIFT'!A22 -> Course Aggregate | D23: =D7 -> 9 | E23: =E7 -> Cu.M | F23: =VLOOKUP(B23,Table13[#All],5,FALSE) -> 307.2 | G23: =G7 -> Cu.M | H23: =(F23*D23) -> 2764.8
B24: ='LEAD & LIFT'!A23 -> Fine Aggregate | D24: =D8 -> 4.5 | E24: =E8 -> Cu.M | F24: =VLOOKUP(B24,Table13[#All],5,FALSE) -> 350.55 | G24: =G8 -> Cu.M | H24: =(F24*D24) -> 1577.475
B25: ='LEAD & LIFT'!A20 -> Cement | D25: =D9 -> 2.16 | E25: =E9 -> MT | F25: =VLOOKUP(B25,Table13[#All],5,FALSE) -> 376.06 | G25: =G9 -> MT | H25: =(F25*D25) -> 812.2896
B27: Total - A | H27: =SUM(H7:H9,H12:H15,H18:H20,H23:H25) -> 49550.665
B29: Water Charges @ | F29: 0.015 | H29: =PRODUCT(H27,F29) -> 743.25997
B30: Electrical Charges @ | F30: 0.01 | H30: =PRODUCT(H27,F30) -> 495.50665
B31: Local Liaisoning & Dispute @ | F31: 0.005 | H31: =PRODUCT(H27,F31) -> 247.75332
B32: Supervision Charges @ | F32: 0.01 | H32: =PRODUCT(H27,F32) -> 495.50665
B33: Engineering & Testing Charges @ | F33: 0.005 | H33: =PRODUCT(H27,F33) -> 247.75332
B34: Site Establishment @ | F34: 0.005 | H34: =PRODUCT(H27,F34) -> 247.75332
B35: Insurance (Labour & Equipments) @ | F35: 0.005 | H35: =PRODUCT(H27,F35) -> 247.75332
B36: Contingency, Safety Compliance & Overhead Charges @ | F36: 0.05 | H36: =PRODUCT(H27,F36) -> 2477.5332
B37: Profit @ | F37: 0.1 | H37: =PRODUCT(H27,F37) -> 4955.0665
B39: Total - B | H39: =SUM(H29:H37) -> 10157.886
B41: Rate for 10Cu.M | H41: =SUM(H27,H39) -> 59708.551
B43: Rate for 1Cu.M | H43: =CEILING(H41/D3,1) -> 5971

Sheet B4
A1: Work Item | B1: B4
B2: PCC M15 (1:2:4)
B3: Rate Analysis for | D3: 10 | E3: Cu.M
A5: Unique_Code | B5: Item | C5: Description | D5: Quantity | E5: Unit | F5: Rate | G5: Per | H5: Amount | I5: Remark
B6: Material
A7: ='TN SOR data - Material'!A77 -> M-0088 | B7: Coarse Aggregate | C7: =VLOOKUP(A7,Table24[#All],2,FALSE) -> HBGS Jelly 20mm size | D7: 8.8 | E7: Cu.M | F7: =VLOOKUP(A7,'TN SOR data - Material'!A:D,4,FALSE) -> 1897.4 | G7: =VLOOKUP(A7,Table24[],3,FALSE) -> Cu.M | H7: =PRODUCT(D7,F7) -> 16697.12
A8: ='TN SOR data - Material'!A94 -> M-0125 | B8: Fine Aggragete | C8: =VLOOKUP(A8,Table24[#All],2,FALSE) -> Crushed Stone Sand (Commercially called M-Sand) | D8: 4.4 | E8: Cu.M | F8: =VLOOKUP(A8,'TN SOR data - Material'!A:D,4,FALSE) -> 1578.8 | G8: =VLOOKUP(A8,Table24[],3,FALSE) -> Cu.M | H8: =PRODUCT(D8,F8) -> 6946.72
A9: ='TN SOR data - Material'!A2 -> M-0001 | B9: Cement (66 bags or 2.20 Cu.M) | C9: =VLOOKUP(A9,Table24[#All],2,FALSE) -> Cement | D9: 3.168 | E9: MT | F9: =VLOOKUP(A9,'TN SOR data - Material'!A:D,4,FALSE) -> 5602.5 | G9: =VLOOKUP(A9,Table24[],3,FALSE) -> MT | H9: =PRODUCT(D9,F9) -> 17748.72
B11: Labour
A12: ='TN SOR data - Labour'!A26 -> L-0029 | B12: Mistri (Head Mason) | C12: =VLOOKUP(A12,'TN SOR data - Labour'!A:D,2,FALSE) -> Mason for Brick Work-I Class | D12: 0.5 | E12: Day | F12: =VLOOKUP(A12,'TN SOR data - Labour'!A:D,4,FALSE) -> 1174 | G12: =VLOOKUP(A12,Table1[],3,FALSE) -> Day | H12: =PRODUCT(D12,F12) -> 587
A13: ='TN SOR data - Labour'!A26 -> L-0029 | B13: Mason | C13: =VLOOKUP(A13,'TN SOR data - Labour'!A:D,2,FALSE) -> Mason for Brick Work-I Class | D13: 1.5 | E13: Day | F13: =VLOOKUP(A13,'TN SOR data - Labour'!A:D,4,FALSE) -> 1174 | G13: =VLOOKUP(A13,Table1[],3,FALSE) -> Day | H13: =PRODUCT(D13,F13) -> 1761
A14: ='TN SOR data - Labour'!A63 -> L-0073 | B14: Male Coolie | C14: =VLOOKUP(A14,'TN SOR data - Labour'!A:D,2,FALSE) -> Mazdoor Category-I | D14: 4 | E14: Day | F14: =VLOOKUP(A14,'TN SOR data - Labour'!A:D,4,FALSE) -> 766 | G14: =VLOOKUP(A14,Table1[],3,FALSE) -> Day | H14: =PRODUCT(D14,F14) -> 3064
A15: ='TN SOR data - Labour'!A85 -> L-0098 | B15: Female Coolie | C15: =VLOOKUP(A15,'TN SOR data - Labour'!A:D,2,FALSE) -> Mazdoor Category-II | D15: 4 | E15: Day | F15: =VLOOKUP(A15,'TN SOR data - Labour'!A:D,4,FALSE) -> 628 | G15: =VLOOKUP(A15,Table1[],3,FALSE) -> Day | H15: =PRODUCT(D15,F15) -> 2512
B17: Equipment
A18: ='SOR data - Equipment'!A15 -> H-0110 | B18: Concrete Mixer | C18: =VLOOKUP(A18,'SOR data - Equipment'!A:D,2,FALSE) -> Mixer Machine with Hopper | D18: 1 | E18: Day | F18: =VLOOKUP(A18,'SOR data - Equipment'!A:D,4,FALSE) -> 1500 | G18: =VLOOKUP(A18,'SOR data - Equipment'!A:D,3,FALSE) -> Day | H18: =PRODUCT(D18,F18) -> 1500
A19: ='SOR data - Equipment'!A14 -> H-0109 | B19: Vibrator | C19: =VLOOKUP(A19,'SOR data - Equipment'!A:D,2,FALSE) -> Hire Charges for Surface Vibrator or Earth Rammer including Fuel | D19: 1 | E19: Day | F19: =VLOOKUP(A19,'SOR data - Equipment'!A:D,4,FALSE) -> 1000 | G19: =VLOOKUP(A19,'SOR data - Equipment'!A:D,3,FALSE) -> Day | H19: =PRODUCT(D19,F19) -> 1000
A20: ='SOR data - Equipment'!A24 -> H-0119 | B20: Formwork | C20: =VLOOKUP(A20,'SOR data - Equipment'!A:D,2,FALSE) -> Hire charges for Concrete Formwork | D20: 1 | E20: LS | F20: =VLOOKUP(A20,'SOR data - Equipment'!A:D,4,FALSE) -> 2500 | G20: =VLOOKUP(A20,'SOR data - Equipment'!A:D,3,FALSE) -> Day | H20: =PRODUCT(D20,F20) -> 2500
B22: Lead & Lift Charges
B23: ='LEAD & LIFT'!A22 -> Course Aggregate | D23: =D7 -> 8.8 | E23: =E7 -> Cu.M | F23: =VLOOKUP(B23,Table13[#All],5,FALSE) -> 307.2 | G23: =G7 -> Cu.M | H23: =(F23*D23) -> 2703.36
B24: ='LEAD & LIFT'!A23 -> Fine Aggregate | D24: =D8 -> 4.4 | E24: =E8 -> Cu.M | F24: =VLOOKUP(B24,Table13[#All],5,FALSE) -> 350.55 | G24: =G8 -> Cu.M | H24: =(F24*D24) -> 1542.42
B25: ='LEAD & LIFT'!A20 -> Cement | D25: =D9 -> 3.168 | E25: =E9 -> MT | F25: =VLOOKUP(B25,Table13[#All],5,FALSE) -> 376.06 | G25: =G9 -> MT | H25: =(F25*D25) -> 1191.3581
B27: Total - A | H27: =SUM(H7:H9,H12:H15,H18:H20,H23:H25) -> 59753.698
B29: Water Charges @ | F29: 0.015 | H29: =PRODUCT(H27,F29) -> 896.30547
B30: Electrical Charges @ | F30: 0.01 | H30: =PRODUCT(H27,F30) -> 597.53698
B31: Local Liaisoning & Dispute @ | F31: 0.005 | H31: =PRODUCT(H27,F31) -> 298.76849
B32: Supervision Charges @ | F32: 0.01 | H32: =PRODUCT(H27,F32) -> 597.53698
B33: Engineering & Testing Charges @ | F33: 0.005 | H33: =PRODUCT(H27,F33) -> 298.76849
B34: Site Establishment @ | F34: 0.005 | H34: =PRODUCT(H27,F34) -> 298.76849
B35: Insurance (Labour & Equipments) @ | F35: 0.005 | H35: =PRODUCT(H27,F35) -> 298.76849
B36: Contingency, Safety Compliance & Overhead Charges @ | F36: 0.05 | H36: =PRODUCT(H27,F36) -> 2987.6849
B37: Profit @ | F37: 0.1 | H37: =PRODUCT(H27,F37) -> 5975.3698
B39: Total - B | H39: =SUM(H29:H37) -> 12249.508
B41: Rate for 10Cu.M | H41: =SUM(H27,H39) -> 72003.206
B43: Rate for 1Cu.M | H43: =CEILING(H41/D3,1) -> 7201

Sheet B5
A1: Work Item | B1: B5
B2: PCC M20 (1:1.5:3)
B3: Rate Analysis for | D3: 10 | E3: Cu.M
A5: Unique_Code | B5: Item | C5: Description | D5: Quantity | E5: Unit | F5: Rate | G5: Per | H5: Amount | I5: Remark
B6: Material
A7: ='TN SOR data - Material'!A77 -> M-0088 | B7: Coarse Aggregate | C7: =VLOOKUP(A7,Table24[#All],2,FALSE) -> HBGS Jelly 20mm size | D7: 8.4 | E7: Cu.M | F7: =VLOOKUP(A7,'TN SOR data - Material'!A:D,4,FALSE) -> 1897.4 | G7: =VLOOKUP(A7,Table24[],3,FALSE) -> Cu.M | H7: =PRODUCT(D7,F7) -> 15938.16
A8: ='TN SOR data - Material'!A94 -> M-0125 | B8: Fine Aggragete | C8: =VLOOKUP(A8,Table24[#All],2,FALSE) -> Crushed Stone Sand (Commercially called M-Sand) | D8: 4.2 | E8: Cu.M | F8: =VLOOKUP(A8,'TN SOR data - Material'!A:D,4,FALSE) -> 1578.8 | G8: =VLOOKUP(A8,Table24[],3,FALSE) -> Cu.M | H8: =PRODUCT(D8,F8) -> 6630.96
A9: ='TN SOR data - Material'!A2 -> M-0001 | B9: Cement (84 bags or 2.80 Cu.M) | C9: =VLOOKUP(A9,Table24[#All],2,FALSE) -> Cement | D9: 4.032 | E9: MT | F9: =VLOOKUP(A9,'TN SOR data - Material'!A:D,4,FALSE) -> 5602.5 | G9: =VLOOKUP(A9,Table24[],3,FALSE) -> MT | H9: =PRODUCT(D9,F9) -> 22589.28
B11: Labour
A12: ='TN SOR data - Labour'!A26 -> L-0029 | B12: Mistri (Head Mason) | C12: =VLOOKUP(A12,'TN SOR data - Labour'!A:D,2,FALSE) -> Mason for Brick Work-I Class | D12: 0.5 | E12: Day | F12: =VLOOKUP(A12,'TN SOR data - Labour'!A:D,4,FALSE) -> 1174 | G12: =VLOOKUP(A12,Table1[],3,FALSE) -> Day | H12: =PRODUCT(D12,F12) -> 587
A13: ='TN SOR data - Labour'!A26 -> L-0029 | B13: Mason | C13: =VLOOKUP(A13,'TN SOR data - Labour'!A:D,2,FALSE) -> Mason for Brick Work-I Class | D13: 1.5 | E13: Day | F13: =VLOOKUP(A13,'TN SOR data - Labour'!A:D,4,FALSE) -> 1174 | G13: =VLOOKUP(A13,Table1[],3,FALSE) -> Day | H13: =PRODUCT(D13,F13) -> 1761
A14: ='TN SOR data - Labour'!A63 -> L-0073 | B14: Male Coolie | C14: =VLOOKUP(A14,'TN SOR data - Labour'!A:D,2,FALSE) -> Mazdoor Category-I | D14: 4 | E14: Day | F14: =VLOOKUP(A14,'TN SOR data - Labour'!A:D,4,FALSE) -> 766 | G14: =VLOOKUP(A14,Table1[],3,FALSE) -> Day | H14: =PRODUCT(D14,F14) -> 3064
A15: ='TN SOR data - Labour'!A85 -> L-0098 | B15: Female Coolie | C15: =VLOOKUP(A15,'TN SOR data - Labour'!A:D,2,FALSE) -> Mazdoor Category-II | D15: 4 | E15: Day | F15: =VLOOKUP(A15,'TN SOR data - Labour'!A:D,4,FALSE) -> 628 | G15: =VLOOKUP(A15,Table1[],3,FALSE) -> Day | H15: =PRODUCT(D15,F15) -> 2512
B17: Equipment
A18: ='SOR data - Equipment'!A15 -> H-0110 | B18: Concrete Mixer | C18: =VLOOKUP(A18,'SOR data - Equipment'!A:D,2,FALSE) -> Mixer Machine with Hopper | D18: 1 | E18: Day | F18: =VLOOKUP(A18,'SOR data - Equipment'!A:D,4,FALSE) -> 1500 | G18: =VLOOKUP(A18,'SOR data - Equipment'!A:D,3,FALSE) -> Day | H18: =PRODUCT(D18,F18) -> 1500
A19: ='SOR data - Equipment'!A14 -> H-0109 | B19: Vibrator | C19: =VLOOKUP(A19,'SOR data - Equipment'!A:D,2,FALSE) -> Hire Charges for Surface Vibrator or Earth Rammer including Fuel | D19: 1 | E19: Day | F19: =VLOOKUP(A19,'SOR data - Equipment'!A:D,4,FALSE) -> 1000 | G19: =VLOOKUP(A19,'SOR data - Equipment'!A:D,3,FALSE) -> Day | H19: =PRODUCT(D19,F19) -> 1000
A20: ='SOR data - Equipment'!A24 -> H-0119 | B20: Formwork | C20: =VLOOKUP(A20,'SOR data - Equipment'!A:D,2,FALSE) -> Hire charges for Concrete Formwork | D20: 1 | E20: LS | F20: =VLOOKUP(A20,'SOR data - Equipment'!A:D,4,FALSE) -> 2500 | G20: =VLOOKUP(A20,'SOR data - Equipment'!A:D,3,FALSE) -> Day | H20: =PRODUCT(D20,F20) -> 2500
B22: Lead & Lift Charges
B23: ='LEAD & LIFT'!A22 -> Course Aggregate | D23: =D7 -> 8.4 | E23: =E7 -> Cu.M | F23: =VLOOKUP(B23,Table13[#All],5,FALSE) -> 307.2 | G23: =G7 -> Cu.M | H23: =(F23*D23) -> 2580.48
B24: ='LEAD & LIFT'!A23 -> Fine Aggregate | D24: =D8 -> 4.2 | E24: =E8 -> Cu.M | F24: =VLOOKUP(B24,Table13[#All],5,FALSE) -> 350.55 | G24: =G8 -> Cu.M | H24: =(F24*D24) -> 1472.31
B25: ='LEAD & LIFT'!A20 -> Cement | D25: =D9 -> 4.032 | E25: =E9 -> MT | F25: =VLOOKUP(B25,Table13[#All],5,FALSE) -> 376.06 | G25: =G9 -> MT | H25: =(F25*D25) -> 1516.2739
B27: Total - A | H27: =SUM(H7:H9,H12:H15,H18:H20,H23:H25) -> 63651.464
B29: Water Charges @ | F29: 0.015 | H29: =PRODUCT(H27,F29) -> 954.77196
B30: Electrical Charges @ | F30: 0.01 | H30: =PRODUCT(H27,F30) -> 636.51464
B31: Local Liaisoning & Dispute @ | F31: 0.005 | H31: =PRODUCT(H27,F31) -> 318.25732
B32: Supervision Charges @ | F32: 0.01 | H32: =PRODUCT(H27,F32) -> 636.51464
B33: Engineering & Testing Charges @ | F33: 0.005 | H33: =PRODUCT(H27,F33) -> 318.25732
B34: Site Establishment @ | F34: 0.005 | H34: =PRODUCT(H27,F34) -> 318.25732
B35: Insurance (Labour & Equipments) @ | F35: 0.005 | H35: =PRODUCT(H27,F35) -> 318.25732
B36: Contingency, Safety Compliance & Overhead Charges @ | F36: 0.05 | H36: =PRODUCT(H27,F36) -> 3182.5732
B37: Profit @ | F37: 0.1 | H37: =PRODUCT(H27,F37) -> 6365.1464
B39: Total - B | H39: =SUM(H29:H37) -> 13048.55
B41: Rate for 10Cu.M | H41: =SUM(H27,H39) -> 76700.014
B43: Rate for 1Cu.M | H43: =CEILING(H41/D3,1) -> 7671

Sheet C1
A1: Work Item | B1: C1
B2: RCC M20 (1:1.5:3)
B3: Rate Analysis for | D3: 10 | E3: Cu.M
A5: Unique_Code | B5: Item | C5: Description | D5: Quantity | E5: Unit | F5: Rate | G5: Per | H5: Amount | I5: Remark
B6: Material
A7: ='TN SOR data - Material'!A77 -> M-0088 | B7: Coarse Aggregate | C7: =VLOOKUP(A7,Table24[#All],2,FALSE) -> HBGS Jelly 20mm size | D7: 8.4 | E7: Cu.M | F7: =VLOOKUP(A7,'TN SOR data - Material'!A:D,4,FALSE) -> 1897.4 | G7: =VLOOKUP(A7,Table24[],3,FALSE) -> Cu.M | H7: =PRODUCT(D7,F7) -> 15938.16
A8: ='TN SOR data - Material'!A94 -> M-0125 | B8: Fine Aggragete | C8: =VLOOKUP(A8,Table24[#All],2,FALSE) -> Crushed Stone Sand (Commercially called M-Sand) | D8: 4.2 | E8: Cu.M | F8: =VLOOKUP(A8,'TN SOR data - Material'!A:D,4,FALSE) -> 1578.8 | G8: =VLOOKUP(A8,Table24[],3,FALSE) -> Cu.M | H8: =PRODUCT(D8,F8) -> 6630.96
A9: ='TN SOR data - Material'!A2 -> M-0001 | B9: Cement (84 bags or 2.80 Cu.M) | C9: =VLOOKUP(A9,Table24[#All],2,FALSE) -> Cement | D9: 4.032 | E9: MT | F9: =VLOOKUP(A9,'TN SOR data - Material'!A:D,4,FALSE) -> 5602.5 | G9: =VLOOKUP(A9,Table24[],3,FALSE) -> MT | H9: =PRODUCT(D9,F9) -> 22589.28
A10: ='TN SOR data - Material'!A3 -> M-0002 | B10: Steel, Mild Steel bars @ 2% = 0.2 Cu.M | C10: =VLOOKUP(A10,Table24[#All],2,FALSE) -> Steel | D10: 1.57 | E10: MT | F10: =VLOOKUP(A10,'TN SOR data - Material'!A:D,4,FALSE) -> 55665 | G10: =VLOOKUP(A10,Table24[],3,FALSE) -> MT | H10: =PRODUCT(D10,F10) -> 87394.05 | I10: 1 Cu.M of steel = 78.5 Quintals 78.5Q x 0.2Cu.M = 15.7Q 1Q = 0.1 MT
A11: ='TN SOR data - Material'!A167 -> M-0189 | B11: Binding Wire | C11: =VLOOKUP(A11,Table24[#All],2,FALSE) -> Binding Wire (Galvanised-18 G) | D11: 2 | E11: Kg | F11: =VLOOKUP(A11,'TN SOR data - Material'!A:D,4,FALSE) -> 56.35 | G11: =VLOOKUP(A11,Table24[],3,FALSE) -> Kg | H11: =PRODUCT(D11,F11) -> 112.7
B13: Labour
A14: ='TN SOR data - Labour'!A26 -> L-0029 | B14: Mistri (Head Mason) | C14: =VLOOKUP(A14,'TN SOR data - Labour'!A:D,2,FALSE) -> Mason for Brick Work-I Class | D14: 1 | E14: Day | F14: =VLOOKUP(A14,'TN SOR data - Labour'!A:D,4,FALSE) -> 1174 | G14: =VLOOKUP(A14,Table1[],3,FALSE) -> Day | H14: =PRODUCT(D14,F14) -> 1174
A15: ='TN SOR data - Labour'!A26 -> L-0029 | B15: Mason | C15: =VLOOKUP(A15,'TN SOR data - Labour'!A:D,2,FALSE) -> Mason for Brick Work-I Class | D15: 3 | E15: Day | F15: =VLOOKUP(A15,'TN SOR data - Labour'!A:D,4,FALSE) -> 1174 | G15: =VLOOKUP(A15,Table1[],3,FALSE) -> Day | H15: =PRODUCT(D15,F15) -> 3522
A16: ='TN SOR data - Labour'!A63 -> L-0073 | B16: Male Coolie | C16: =VLOOKUP(A16,'TN SOR data - Labour'!A:D,2,FALSE) -> Mazdoor Category-I | D16: 4 | E16: Day | F16: =VLOOKUP(A16,'TN SOR data - Labour'!A:D,4,FALSE) -> 766 | G16: =VLOOKUP(A16,Table1[],3,FALSE) -> Day | H16: =PRODUCT(D16,F16) -> 3064
A17: ='TN SOR data - Labour'!A85 -> L-0098 | B17: Female Coolie | C17: =VLOOKUP(A17,'TN SOR data - Labour'!A:D,2,FALSE) -> Mazdoor Category-II | D17: 4 | E17: Day | F17: =VLOOKUP(A17,'TN SOR data - Labour'!A:D,4,FALSE) -> 628 | G17: =VLOOKUP(A17,Table1[],3,FALSE) -> Day | H17: =PRODUCT(D17,F17) -> 2512
A18: ='TN SOR data - Labour'!A52 -> L-0060 | B18: Blacksmith (II class) for bar bending | C18: =VLOOKUP(A18,'TN SOR data - Labour'!A:D,2,FALSE) -> Blacksmith-II Class | D18: 8 | E18: Day | F18: =VLOOKUP(A18,'TN SOR data - Labour'!A:D,4,FALSE) -> 867 | G18: =VLOOKUP(A18,Table1[],3,FALSE) -> Day | H18: =PRODUCT(D18,F18) -> 6936
A19: ='TN SOR data - Labour'!A85 -> L-0098 | B19: Mazdoor for bar bending | C19: =VLOOKUP(A19,'TN SOR data - Labour'!A:D,2,FALSE) -> Mazdoor Category-II | D19: 8 | E19: Day | F19: =VLOOKUP(A19,'TN SOR data - Labour'!A:D,4,FALSE) -> 628 | G19: =VLOOKUP(A19,Table1[],3,FALSE) -> Day | H19: =PRODUCT(D19,F19) -> 5024
A20: ='TN SOR data - Labour'!A55 -> L-0063 | B20: Carpenter (II class) for centering & shuttering | C20: =VLOOKUP(A20,'TN SOR data - Labour'!A:D,2,FALSE) -> Carpenter-II Class | D20: 10 | E20: Day | F20: =VLOOKUP(A20,'TN SOR data - Labour'!A:D,4,FALSE) -> 1096 | G20: =VLOOKUP(A20,Table1[],3,FALSE) -> Day | H20: =PRODUCT(D20,F20) -> 10960
A21: ='TN SOR data - Labour'!A85 -> L-0098 | B21: Mazdoor for centering & shuttering | C21: =VLOOKUP(A21,'TN SOR data - Labour'!A:D,2,FALSE) -> Mazdoor Category-II | D21: 10 | E21: Day | F21: =VLOOKUP(A21,'TN SOR data - Labour'!A:D,4,FALSE) -> 628 | G21: =VLOOKUP(A21,Table1[],3,FALSE) -> Day | H21: =PRODUCT(D21,F21) -> 6280
B23: Equipment
A24: ='SOR data - Equipment'!A15 -> H-0110 | B24: Concrete Mixer | C24: =VLOOKUP(A24,'SOR data - Equipment'!A:D,2,FALSE) -> Mixer Machine with Hopper | D24: 0.75 | E24: Day | F24: =VLOOKUP(A24,'SOR data - Equipment'!A:D,4,FALSE) -> 1500 | G24: =VLOOKUP(A24,'SOR data - Equipment'!A:D,3,FALSE) -> Day | H24: =PRODUCT(D24,F24) -> 1125
A25: ='SOR data - Equipment'!A14 -> H-0109 | B25: Vibrator | C25: =VLOOKUP(A25,'SOR data - Equipment'!A:D,2,FALSE) -> Hire Charges for Surface Vibrator or Earth Rammer including Fuel | D25: 1 | E25: LS | F25: =VLOOKUP(A25,'SOR data - Equipment'!A:D,4,FALSE) -> 1000 | G25: =VLOOKUP(A25,'SOR data - Equipment'!A:D,3,FALSE) -> Day | H25: =PRODUCT(D25,F25) -> 1000
A26: ='SOR data - Equipment'!A24 -> H-0119 | B26: Formwork | C26: =VLOOKUP(A26,'SOR data - Equipment'!A:D,2,FALSE) -> Hire charges for Concrete Formwork | D26: 1 | E26: LS | F26: =VLOOKUP(A26,'SOR data - Equipment'!A:D,4,FALSE) -> 2500 | G26: =VLOOKUP(A26,'SOR data - Equipment'!A:D,3,FALSE) -> Day | H26: =PRODUCT(D26,F26) -> 2500
A27: ='SOR data - Equipment'!A25 -> H-0120 | B27: Shuttering | C27: =VLOOKUP(A27,'SOR data - Equipment'!A:D,2,FALSE) -> Hire charges for Concrete Shuttering | D27: 1 | E27: LS | F27: =VLOOKUP(A27,'SOR data - Equipment'!A:D,4,FALSE) -> 3000 | G27: =VLOOKUP(A27,'SOR data - Equipment'!A:D,3,FALSE) -> Day | H27: =PRODUCT(D27,F27) -> 3000
A28: ='SOR data - Equipment'!A26 -> H-0121 | B28: Tools and Tackles | C28: =VLOOKUP(A28,'SOR data - Equipment'!A:D,2,FALSE) -> Hire charges for Concrete Tools and Tackles | D28: 1 | E28: LS | F28: =VLOOKUP(A28,'SOR data - Equipment'!A:D,4,FALSE) -> 2000 | G28: =VLOOKUP(A28,'SOR data - Equipment'!A:D,3,FALSE) -> Day | H28: =PRODUCT(D28,F28) -> 2000
B30: Lead & Lift Charges
B31: ='LEAD & LIFT'!A22 -> Course Aggregate | D31: =D7 -> 8.4 | E31: =E7 -> Cu.M | F31: =VLOOKUP(B31,Table13[#All],5,FALSE) -> 307.2 | G31: =G7 -> Cu.M | H31: =(F31*D31) -> 2580.48
B32: ='LEAD & LIFT'!A23 -> Fine Aggregate | D32: =D8 -> 4.2 | E32: =E8 -> Cu.M | F32: =VLOOKUP(B32,Table13[#All],5,FALSE) -> 350.55 | G32: =G8 -> Cu.M | H32: =(F32*D32) -> 1472.31
B33: ='LEAD & LIFT'!A20 -> Cement | D33: =D9 -> 4.032 | E33: =E9 -> MT | F33: =VLOOKUP(B33,Table13[#All],5,FALSE) -> 376.06 | G33: =G9 -> MT | H33: =(F33*D33) -> 1516.2739
B34: ='LEAD & LIFT'!A21 -> Steel | D34: =D10 -> 1.57 | E34: =E10 -> MT | F34: =VLOOKUP(B34,Table13[#All],5,FALSE) -> 350.86 | G34: =G10 -> MT | H34: =(F34*D34) -> 550.8502
B36: Total - A | H36: =SUM(H7:H11,H14:H21,H24:H28,H31:H34) -> 187882.06
B38: Water Charges @ | F38: 0.015 | H38: =PRODUCT(H36,F38) -> 2818.231
B39: Electrical Charges @ | F39: 0.01 | H39: =PRODUCT(H36,F39) -> 1878.8206
B40: Local Liaisoning & Dispute @ | F40: 0.005 | H40: =PRODUCT(H36,F40) -> 939.41032
B41: Supervision Charges @ | F41: 0.01 | H41: =PRODUCT(H36,F41) -> 1878.8206
B42: Engineering & Testing Charges @ | F42: 0.005 | H42: =PRODUCT(H36,F42) -> 939.41032
B43: Site Establishment @ | F43: 0.005 | H43: =PRODUCT(H36,F43) -> 939.41032
B44: Insurance (Labour & Equipments) @ | F44: 0.005 | H44: =PRODUCT(H36,F44) -> 939.41032
B45: Contingency, Safety Compliance & Overhead Charges @ | F45: 0.05 | H45: =PRODUCT(H36,F45) -> 9394.1032
B46: Profit @ | F46: 0.1 | H46: =PRODUCT(H36,F46) -> 18788.206
...

Sheet C2
A1: Work Item | B1: C2
B2: RCC M25 (1:1:2)
B3: Rate Analysis for | D3: 10 | E3: Cu.M
A5: Unique_Code | B5: Item | C5: Description | D5: Quantity | E5: Unit | F5: Rate | G5: Per | H5: Amount | I5: Remark
B6: Material
A7: ='TN SOR data - Material'!A77 -> M-0088 | B7: Coarse Aggregate | C7: =VLOOKUP(A7,Table24[#All],2,FALSE) -> HBGS Jelly 20mm size | D7: 8.2 | E7: Cu.M | F7: =VLOOKUP(A7,'TN SOR data - Material'!A:D,4,FALSE) -> 1897.4 | G7: =VLOOKUP(A7,Table24[],3,FALSE) -> Cu.M | H7: =PRODUCT(D7,F7) -> 15558.68
A8: ='TN SOR data - Material'!A94 -> M-0125 | B8: Fine Aggragete | C8: =VLOOKUP(A8,Table24[#All],2,FALSE) -> Crushed Stone Sand (Commercially called M-Sand) | D8: 4.1 | E8: Cu.M | F8: =VLOOKUP(A8,'TN SOR data - Material'!A:D,4,FALSE) -> 1578.8 | G8: =VLOOKUP(A8,Table24[],3,FALSE) -> Cu.M | H8: =PRODUCT(D8,F8) -> 6473.08
A9: ='TN SOR data - Material'!A2 -> M-0001 | B9: Cement (90 bags or 3.125 Cu.M) | C9: =VLOOKUP(A9,Table24[#All],2,FALSE) -> Cement | D9: 4.5 | E9: MT | F9: =VLOOKUP(A9,'TN SOR data - Material'!A:D,4,FALSE) -> 5602.5 | G9: =VLOOKUP(A9,Table24[],3,FALSE) -> MT | H9: =PRODUCT(D9,F9) -> 25211.25
A10: ='TN SOR data - Material'!A3 -> M-0002 | B10: Steel, Mild Steel bars @ 2% = 0.2 Cu.M | C10: =VLOOKUP(A10,Table24[#All],2,FALSE) -> Steel | D10: 1.57 | E10: MT | F10: =VLOOKUP(A10,'TN SOR data - Material'!A:D,4,FALSE) -> 55665 | G10: =VLOOKUP(A10,Table24[],3,FALSE) -> MT | H10: =PRODUCT(D10,F10) -> 87394.05 | I10: 1 Cu.M of steel = 78.5 Quintals 78.5Q x 0.2Cu.M = 15.7Q 1Q = 0.1 MT
A11: ='TN SOR data - Material'!A167 -> M-0189 | B11: Binding Wire | C11: =VLOOKUP(A11,Table24[#All],2,FALSE) -> Binding Wire (Galvanised-18 G) | D11: 2 | E11: Kg | F11: =VLOOKUP(A11,'TN SOR data - Material'!A:D,4,FALSE) -> 56.35 | G11: =VLOOKUP(A11,Table24[],3,FALSE) -> Kg | H11: =PRODUCT(D11,F11) -> 112.7
B13: Labour
A14: ='TN SOR data - Labour'!A26 -> L-0029 | B14: Mistri (Head Mason) | C14: =VLOOKUP(A14,'TN SOR data - Labour'!A:D,2,FALSE) -> Mason for Brick Work-I Class | D14: 1 | E14: Day | F14: =VLOOKUP(A14,'TN SOR data - Labour'!A:D,4,FALSE) -> 1174 | G14: =VLOOKUP(A14,Table1[],3,FALSE) -> Day | H14: =PRODUCT(D14,F14) -> 1174
A15: ='TN SOR data - Labour'!A26 -> L-0029 | B15: Mason | C15: =VLOOKUP(A15,'TN SOR data - Labour'!A:D,2,FALSE) -> Mason for Brick Work-I Class | D15: 3 | E15: Day | F15: =VLOOKUP(A15,'TN SOR data - Labour'!A:D,4,FALSE) -> 1174 | G15: =VLOOKUP(A15,Table1[],3,FALSE) -> Day | H15: =PRODUCT(D15,F15) -> 3522
A16: ='TN SOR data - Labour'!A63 -> L-0073 | B16: Male Coolie | C16: =VLOOKUP(A16,'TN SOR data - Labour'!A:D,2,FALSE) -> Mazdoor Category-I | D16: 4 | E16: Day | F16: =VLOOKUP(A16,'TN SOR data - Labour'!A:D,4,FALSE) -> 766 | G16: =VLOOKUP(A16,Table1[],3,FALSE) -> Day | H16: =PRODUCT(D16,F16) -> 3064
A17: ='TN SOR data - Labour'!A85 -> L-0098 | B17: Female Coolie | C17: =VLOOKUP(A17,'TN SOR data - Labour'!A:D,2,FALSE) -> Mazdoor Category-II | D17: 4 | E17: Day | F17: =VLOOKUP(A17,'TN SOR data - Labour'!A:D,4,FALSE) -> 628 | G17: =VLOOKUP(A17,Table1[],3,FALSE) -> Day | H17: =PRODUCT(D17,F17) -> 2512
A18: ='TN SOR data - Labour'!A52 -> L-0060 | B18: Blacksmith (II class) for bar bending | C18: =VLOOKUP(A18,'TN SOR data - Labour'!A:D,2,FALSE) -> Blacksmith-II Class | D18: 8 | E18: Day | F18: =VLOOKUP(A18,'TN SOR data - Labour'!A:D,4,FALSE) -> 867 | G18: =VLOOKUP(A18,Table1[],3,FALSE) -> Day | H18: =PRODUCT(D18,F18) -> 6936
A19: ='TN SOR data - Labour'!A85 -> L-0098 | B19: Mazdoor for bar bending | C19: =VLOOKUP(A19,'TN SOR data - Labour'!A:D,2,FALSE) -> Mazdoor Category-II | D19: 8 | E19: Day | F19: =VLOOKUP(A19,'TN SOR data - Labour'!A:D,4,FALSE) -> 628 | G19: =VLOOKUP(A19,Table1[],3,FALSE) -> Day | H19: =PRODUCT(D19,F19) -> 5024
A20: ='TN SOR data - Labour'!A55 -> L-0063 | B20: Carpenter (II class) for centering & shuttering | C20: =VLOOKUP(A20,'TN SOR data - Labour'!A:D,2,FALSE) -> Carpenter-II Class | D20: 10 | E20: Day | F20: =VLOOKUP(A20,'TN SOR data - Labour'!A:D,4,FALSE) -> 1096 | G20: =VLOOKUP(A20,Table1[],3,FALSE) -> Day | H20: =PRODUCT(D20,F20) -> 10960
A21: ='TN SOR data - Labour'!A85 -> L-0098 | B21: Mazdoor for centering & shuttering | C21: =VLOOKUP(A21,'TN SOR data - Labour'!A:D,2,FALSE) -> Mazdoor Category-II | D21: 10 | E21: Day | F21: =VLOOKUP(A21,'TN SOR data - Labour'!A:D,4,FALSE) -> 628 | G21: =VLOOKUP(A21,Table1[],3,FALSE) -> Day | H21: =PRODUCT(D21,F21) -> 6280
B23: Equipment
A24: ='SOR data - Equipment'!A15 -> H-0110 | B24: Concrete Mixer | C24: =VLOOKUP(A24,'SOR data - Equipment'!A:D,2,FALSE) -> Mixer Machine with Hopper | D24: 0.75 | E24: Day | F24: =VLOOKUP(A24,'SOR data - Equipment'!A:D,4,FALSE) -> 1500 | G24: =VLOOKUP(A24,'SOR data - Equipment'!A:D,3,FALSE) -> Day | H24: =PRODUCT(D24,F24) -> 1125
A25: ='SOR data - Equipment'!A14 -> H-0109 | B25: Vibrator | C25: =VLOOKUP(A25,'SOR data - Equipment'!A:D,2,FALSE) -> Hire Charges for Surface Vibrator or Earth Rammer including Fuel | D25: 1 | E25: LS | F25: =VLOOKUP(A25,'SOR data - Equipment'!A:D,4,FALSE) -> 1000 | G25: =VLOOKUP(A25,'SOR data - Equipment'!A:D,3,FALSE) -> Day | H25: =PRODUCT(D25,F25) -> 1000
A26: ='SOR data - Equipment'!A24 -> H-0119 | B26: Formwork | C26: =VLOOKUP(A26,'SOR data - Equipment'!A:D,2,FALSE) -> Hire charges for Concrete Formwork | D26: 1 | E26: LS | F26: =VLOOKUP(A26,'SOR data - Equipment'!A:D,4,FALSE) -> 2500 | G26: =VLOOKUP(A26,'SOR data - Equipment'!A:D,3,FALSE) -> Day | H26: =PRODUCT(D26,F26) -> 2500
A27: ='SOR data - Equipment'!A25 -> H-0120 | B27: Shuttering | C27: =VLOOKUP(A27,'SOR data - Equipment'!A:D,2,FALSE) -> Hire charges for Concrete Shuttering | D27: 1 | E27: LS | F27: =VLOOKUP(A27,'SOR data - Equipment'!A:D,4,FALSE) -> 3000 | G27: =VLOOKUP(A27,'SOR data - Equipment'!A:D,3,FALSE) -> Day | H27: =PRODUCT(D27,F27) -> 3000
A28: ='SOR data - Equipment'!A26 -> H-0121 | B28: Tools and Tackles | C28: =VLOOKUP(A28,'SOR data - Equipment'!A:D,2,FALSE) -> Hire charges for Concrete Tools and Tackles | D28: 1 | E28: LS | F28: =VLOOKUP(A28,'SOR data - Equipment'!A:D,4,FALSE) -> 2000 | G28: =VLOOKUP(A28,'SOR data - Equipment'!A:D,3,FALSE) -> Day | H28: =PRODUCT(D28,F28) -> 2000
B30: Lead & Lift Charges
B31: ='LEAD & LIFT'!A22 -> Course Aggregate | D31: =D7 -> 8.2 | E31: =E7 -> Cu.M | F31: =VLOOKUP(B31,Table13[#All],5,FALSE) -> 307.2 | G31: =G7 -> Cu.M | H31: =(F31*D31) -> 2519.04
B32: ='LEAD & LIFT'!A23 -> Fine Aggregate | D32: =D8 -> 4.1 | E32: =E8 -> Cu.M | F32: =VLOOKUP(B32,Table13[#All],5,FALSE) -> 350.55 | G32: =G8 -> Cu.M | H32: =(F32*D32) -> 1437.255
B33: ='LEAD & LIFT'!A20 -> Cement | D33: =D9 -> 4.5 | E33: =E9 -> MT | F33: =VLOOKUP(B33,Table13[#All],5,FALSE) -> 376.06 | G33: =G9 -> MT | H33: =(F33*D33) -> 1692.27
B34: ='LEAD & LIFT'!A21 -> Steel | D34: =D10 -> 1.57 | E34: =E10 -> MT | F34: =VLOOKUP(B34,Table13[#All],5,FALSE) -> 350.86 | G34: =G10 -> MT | H34: =(F34*D34) -> 550.8502
B36: Total - A | H36: =SUM(H7:H11,H14:H21,H24:H28,H31:H34) -> 190046.18
B38: Water Charges @ | F38: 0.015 | H38: =PRODUCT(H36,F38) -> 2850.6926
B39: Electrical Charges @ | F39: 0.01 | H39: =PRODUCT(H36,F39) -> 1900.4618
B40: Local Liaisoning & Dispute @ | F40: 0.005 | H40: =PRODUCT(H36,F40) -> 950.23088
B41: Supervision Charges @ | F41: 0.01 | H41: =PRODUCT(H36,F41) -> 1900.4618
B42: Engineering & Testing Charges @ | F42: 0.005 | H42: =PRODUCT(H36,F42) -> 950.23088
B43: Site Establishment @ | F43: 0.005 | H43: =PRODUCT(H36,F43) -> 950.23088
B44: Insurance (Labour & Equipments) @ | F44: 0.005 | H44: =PRODUCT(H36,F44) -> 950.23088
B45: Contingency, Safety Compliance & Overhead Charges @ | F45: 0.05 | H45: =PRODUCT(H36,F45) -> 9502.3088
B46: Profit @ | F46: 0.1 | H46: =PRODUCT(H36,F46) -> 19004.618
...

Sheet C3
A1: Work Item | B1: C3
B2: RCC M30 (1:0.75:1.5)
B3: Rate Analysis for | D3: 10 | E3: Cu.M
A5: Unique_Code | B5: Item | C5: Description | D5: Quantity | E5: Unit | F5: Rate | G5: Per | H5: Amount | I5: Remark
B6: Material
A7: ='TN SOR data - Material'!A77 -> M-0088 | B7: Coarse Aggregate | C7: =VLOOKUP(A7,Table24[#All],2,FALSE) -> HBGS Jelly 20mm size | D7: 8 | E7: Cu.M | F7: =VLOOKUP(A7,'TN SOR data - Material'!A:D,4,FALSE) -> 1897.4 | G7: =VLOOKUP(A7,Table24[],3,FALSE) -> Cu.M | H7: =PRODUCT(D7,F7) -> 15179.2
